<mujoco>
    <compiler angle="radian" autolimits="true"/>
    <option gravity="0 0 -9.81"/>
    <option timestep="0.0001" integrator = "RK4"/> 
    

    <default>

    <default class="WLR">
        
        <geom friction="0.6" margin="0.001"/>
      <joint axis="1 0 0" damping="2" armature="0.01" frictionloss="0.2"/>
      <position kp="200" forcerange="-20 20"/>
    
        <default class="hip_joint">
            <joint type="hinge" axis="1 0 0" pos = "-0.01 0.0 0.09"  range="-1.5708 1.5708"  />
            <position ctrlrange="-1.5708 1.5708" forcelimited="true" forcerange="-40 40"/>
        </default>
        <default class="knee_joint">
            <joint type="hinge" axis="1 0 0" pos = "0 0.0 0.09"  range="-0.785398 2.0944" />
             <position ctrlrange="-0.785398 2.0944" forcelimited="true" forcerange="-40 40"/>
        </default>
        <default class="wheel_joint">
            <joint type="hinge" axis="-1 0 0"/>
            <motor ctrlrange="-200.5 200.5"/>
        </default>

 
    <default class="visual">
        <geom group="1" type="mesh" contype="0" conaffinity="0" material="offwhite"/>
    </default>

   
    <default class="collision">
        <geom group="3" type="capsule" friction="0.7 0.5 0.1"/>
        
         <default class="body">
            <geom type="box" size="0.1 0.11 0.03" />
        </default>

         <default class="fb_box">
            <geom type="box" size="0.07 0.045 0.03" />
        </default>
        
        <default class="leg_link_collision">
            <geom type="capsule" size="0.02 0.07"/>
        </default>

        <default class="hip">
            <geom type="cylinder" size="0.04 0.02" quat="0.707 0 0.707 0"/>
        </default>


        <default class="knee">
            <geom type="cylinder" size="0.01 0.025" quat="0.707 0 0.707 0"/>
        </default>

        <default class="leg_collision">
            <geom size="0.01 0.08"/>

        </default>

        <default class="wheel_collision">
            <geom type="cylinder" size="0.05 0.015"  quat="0.707 0 0.707 0" friction="0.8 0.2 0.02"/>
            
        </default>
        <default class="wheel_cup">
            <geom type="cylinder" size="0.005 0.025" quat="0.707 0 0.707 0"/>
        </default>
    </default>
 </default>
</default>



 <asset>
        <material name="dark" specular="0" shininess="0.25" rgba="0.2 0.2 0.2 1"/>

        <material name="offwhite" specular="0" shininess="0.25" rgba="0.45 0.45 0.45 1"/>
        

        <mesh class="WLR" name="base" file="Chassis.STL"/>
        <mesh class="WLR" name="ll" file="Leg_Link.STL"/>
        <mesh class="WLR" name="leg" file="Leg.STL"/>
        <mesh class="WLR" name="wheel" file="Wheel.STL"/>
    </asset>

    <worldbody>

   


     <body name="chassis" pos="0 0 .38" childclass="WLR">
      <inertial mass="4.8" pos="0.1 0.183 0.06"
            fullinertia="0.0154 0.01468 0.02815 0 0 0"/>

        <geom class="body" pos = "0.1 0.2 0.03"/>
        <geom name = "back_box" class="fb_box" pos = "0.1 0.045 0.03" />
        <geom name = "front_box" class="fb_box" pos = "0.1 0.355 0.03"/>
        <!-- Visual -->
        <geom class="visual" mesh="base" material="offwhite"/>
        <joint name="body_joint" type="free" />

       
        <site name="imu_site" pos="0.1 0.2 -0.01" size="0.005" rgba="0 0 0 0"/>

        <body name="BR_hip" pos="0.19 0.045 0.03">
         <site name="BR_end_effector" pos="0 0.0 -0.224" size="0.01" type="sphere" rgba="0 0 0 0"/>
        <inertial mass="0.7" pos="0 0 0"
            fullinertia="0.0006 0.0006 0.0009 0 0 0"/> <!-- Hip -->
        <geom class="hip"/>
        <body name="BR_LL" pos="0.04 0 -0.09">
        <inertial mass="0.5" pos="0 0 0"
            fullinertia="0.0018 0.0018 0.00018 0 0 0"/> 
                <geom class="leg_link_collision"/>
                
                <geom class="visual" mesh="ll" pos="-0.1 -0.04 -0.105" />
                <joint  name = "BR_hip_joint" type="hinge" axis="1 0 0" pos = "-0.01 0.0 0.09"  range="-1.5708 1.5708"  />

            <body name="BR_knee"  pos = "0.0 0.0 -0.09">
            <geom class="knee"/>
            <body name="BR_Leg" pos="-0.025 0.0 -0.09">
            <inertial mass="0.5" pos="0 0 0.0265"
                fullinertia="0.0012 0.0012 0.000015 0 0 0"/>
                <geom class="leg_collision"/>
                <!-- Visual -->
                <geom class="visual" mesh="leg" pos="-0.005 -0.03 -0.1" material="offwhite"/>
                <joint class="knee_joint" name = "BR_knee_joint"/>
                <site name="BR_wheel_site" pos="0.0 -0.04 -0.115" size="0.005" rgba="0 0 0 0"/>
                <body name="BR_Wheel" pos="0.03 0.0 -0.09">
                <inertial mass="0.2" pos="0 0 0"
                     fullinertia="0.00015 0.00015 0.00025 0 0 0"/> 
                     <geom class="wheel_collision" name="BR_wheel_collision"/>
                    <geom class="wheel_cup"  pos = "0.0 0.0 0.0"/>
                    <!-- Visual -->
                    <geom class="visual" mesh="wheel" pos = "-0.02 -0.0513 -0.05" material = "dark" />
                     
                     <joint class="wheel_joint" name = "BR_wheel_joint"/>
                     
            </body>
             
            </body>
         </body>
            
        </body>
    </body>
    

        <body name="FR_hip" pos="0.19 0.355 0.03">
        <inertial mass="0.7" pos="0 0 0"
    fullinertia="0.0005 0.0005 0.0008 0 0 0"/>
     <site name="BR_hip_site" pos="0 0.09 -2." size="0.01" type="sphere" rgba="1 0 1 1"/>
        
        <geom class="hip"/>
        <body name="FR_LL" pos="0.04 0 -0.09">
       <inertial mass="0.5" pos="0 0 0"
            fullinertia="0.0018 0.0018 0.00018 0 0 0"/> 
             <!-- Collision -->
                <geom class="leg_link_collision"/>
                
                <geom class="visual" mesh="ll" pos="-0.1 -0.04 -0.105"/>
                <joint class="hip_joint" name = "FR_hip_joint"/>
                <body name="FR_knee"  pos = "0.00 0.0 -0.09">
                <geom class="knee"/>
            <body name="FR_Leg" pos="-0.025 0.0 -0.09">
            <inertial mass="0.5" pos="0 0 0.0265"
                fullinertia="0.0012 0.0012 0.000015 0 0 0"/>
                <geom class="leg_collision"/>
                
             
                <geom class="visual" mesh="leg" pos="-0.005 -0.03 -0.1" material="offwhite"/>
                <joint class="knee_joint" name = "FR_knee_joint"/>
                <site name="FR_wheel_site" pos="0.0 -0.04 -0.115" size="0.005" rgba="0 0 0 0"/>
                <body name="FR_Wheel" pos="0.03 0.0 -0.09">
                <inertial mass="0.2" pos="0 0 0"
                        fullinertia="0.00015 0.00015 0.00025 0 0 0"/>
                     <geom class="wheel_collision" name="FR_wheel_collision"/>
                    <geom class="wheel_cup"  pos = "0.0 0.0 0.0"/>
          
                    <geom class="visual" mesh="wheel" pos = "-0.02 -0.0513 -0.05" material = "dark"/>
                     <joint class="wheel_joint" name = "FR_wheel_joint"/>
                    


            </body>
            </body>
            </body>
        </body>
    </body>

         <body name="BL_hip" pos="0.01 0.045 0.03">
        <inertial mass="0.7" pos="0 0 0"
            fullinertia="0.0006 0.0006 0.0009 0 0 0"/> 
        <geom class="hip"/>
        <body name="BL_LL" pos="-0.04 0 -0.09">
             <inertial mass="0.5" pos="0 0 0"
                fullinertia="0.0018 0.0018 0.00018 0 0 0"/> 
             <!-- Collision -->
                <geom class="leg_link_collision"/>
                
                <geom class="visual" mesh="ll" pos="0.1 0.04 -0.105" quat="0 0 0 1"/>
                <joint class="hip_joint" name = "BL_hip_joint"/>
            <body name="BL_knee"  pos = "0 0.0 -0.09">
                    <geom class="knee"/>
            <body name="BL_Leg" pos="0.025 0.0 -0.09">
             <inertial mass="0.5" pos="0 0 0.0265"
                fullinertia="0.0012 0.0012 0.000015 0 0 0"/>
                <geom class="leg_collision" />
              
                <geom class="visual" mesh="leg" pos="0.005 0.03 -0.1" quat="0 0 0 1" material="offwhite"/>
                <joint class="knee_joint" name = "BL_knee_joint" />
                <site name="BL_wheel_site" pos="0.0 -0.04 -0.115" size="0.005" rgba="0 0 0 0"/>

                <body name="BL_Wheel" pos="-0.03 0.0 -0.09">
                <inertial mass="0.2" pos="0 0 0"
                    fullinertia="0.00015 0.00015 0.00025 0 0 0"/> 
                     <geom class="wheel_collision" name="BL_wheel_collision"/>
                    <geom class="wheel_cup"  pos = "0.0 0.0 0.0"/>
                 
                    <geom class="visual" mesh="wheel" pos = "-0.01 -0.0487 -0.05" material = "dark"/>
                     <joint class="wheel_joint" name = "BL_wheel_joint"/>

            </body>
            </body>
                
            </body>
        </body>
    </body>

         <body name="FL_hip" pos="0.01 0.355 0.03">
         <inertial mass="0.7" pos="0 0 0"
            fullinertia="0.0006 0.0006 0.0009 0 0 0"/> 
        <geom class="hip"/>
        <body name="FL_LL" pos="-0.04 0 -0.09">
        <inertial mass="0.5" pos="0 0 0"
            fullinertia="0.0018 0.0018 0.00018 0 0 0"/> 
            
                <geom class="leg_link_collision"/>
                
                <geom class="visual" mesh="ll" pos="0.1 0.04 -0.105" quat="0 0 0 1"/>
                <joint class="hip_joint" name = "FL_hip_joint"/>
                <body name="FL_knee"  pos = "0 0.0 -0.09">
                    <geom class="knee"/>
            <body name="FL_Leg" pos="0.025 0.0 -0.09">
            <inertial mass="0.5" pos="0 0 0.0265"
                    fullinertia="0.0012 0.0012 0.000015 0 0 0"/>
                <geom class="leg_collision" />
                
              
                <geom class="visual" mesh="leg" pos="0.005 0.03 -0.1" quat="0 0 0 1" material="offwhite"/>
                <joint class="knee_joint" name = "FL_knee_joint"/>
                <site name="FL_wheel_site" pos="0.0 -0.04 -0.115" size="0.005" rgba="0 0 0 0"/>

                <body name="FL_Wheel" pos="-0.03 0.0 -0.09">
                     <inertial mass="0.2" pos="0 0 0"
                        fullinertia="0.00015 0.00015 0.00025 0 0 0"/>
                    <geom class="wheel_collision" name="FL_wheel_collision"/>
                    <geom class="wheel_cup"  pos = "0.0 0.0 0.0"/>
                
                    <geom class="visual" mesh="wheel" pos = "-0.01 -0.0487 -0.05" material = "dark"/>
                     <joint class="wheel_joint" name = "FL_wheel_joint"/>
                     

            </body>
            </body>
                
            </body>
        </body>

    </body>
</body>
            
    </worldbody>

    <actuator>

        <!--hip joints motors-->

        <!--right hip joints motors-->
        <position class= "hip_joint" name="BR_hip_joint_motor" joint="BR_hip_joint"/>
        <position class= "hip_joint" name="FR_hip_joint_motor" joint="FR_hip_joint"/>
        <!--left hip joints motors-->
        
        <position class= "hip_joint" name="FL_hip_joint_motor" joint="FL_hip_joint"/>
        <position class= "hip_joint" name="BL_hip_joint_motor" joint="BL_hip_joint"/>
        <!--knee joints motors-->

        <!--right knee joints motors-->
        <position class= "knee_joint" name="BR_knee_joint_motor" joint="BR_knee_joint" />
        <position class= "knee_joint" name="FR_knee_joint_motor" joint="FR_knee_joint"/>
        <!--left knee joints motors-->
        <position class= "knee_joint" name="FL_knee_joint_motor" joint="FL_knee_joint"/>
        <position class= "knee_joint" name="BL_knee_joint_motor" joint="BL_knee_joint"/>
      

        <!--wheel joints motors-->

        <!--right wheel joints motors-->
        <motor class= "wheel_joint" name="BR_wheel_joint_motor" joint="BR_wheel_joint"/>
        <motor class= "wheel_joint" name="FR_wheel_joint_motor" joint="FR_wheel_joint"/>
        <!--left wheel joints motors-->
        <motor class= "wheel_joint" name="FL_wheel_joint_motor" joint="FL_wheel_joint" />
        <motor class= "wheel_joint" name="BL_wheel_joint_motor" joint="BL_wheel_joint" />
       
        
        
        

    </actuator>

    <sensor>

    <accelerometer name="imu_accel" site="imu_site"/>
    <gyro name="imu_gyro" site="imu_site"/>

    <!-- Hip Joint Sensors -->
    <jointpos name="BR_hip_pos_test" joint="BR_hip_joint"/>
    <jointpos name="FR_hip_pos_test" joint="FR_hip_joint"/>
    <jointpos name="BL_hip_pos_test" joint="BL_hip_joint"/>
    <jointpos name="FL_hip_pos_test" joint="FL_hip_joint"/>

    <jointpos name="BR_hip_pos" joint="BR_hip_joint"/>
    <jointpos name="FR_hip_pos" joint="FR_hip_joint"/>
    <jointpos name="BL_hip_pos" joint="BL_hip_joint"/>
    <jointpos name="FL_hip_pos" joint="FL_hip_joint"/>
    

    <jointpos name="BR_knee_pos_test" joint="BR_knee_joint"/>
    <jointpos name="FR_knee_pos_test" joint="FR_knee_joint"/>
    <jointpos name="BL_knee_pos_test" joint="BL_knee_joint"/>
    <jointpos name="FL_knee_pos_test" joint="FL_knee_joint"/>

    <!-- Knee Joint Sensors -->
    <jointpos name="BR_knee_pos" joint="BR_knee_joint"/>
    <jointpos name="FR_knee_pos" joint="FR_knee_joint"/>
    <jointpos name="BL_knee_pos" joint="BL_knee_joint"/>
    <jointpos name="FL_knee_pos" joint="FL_knee_joint"/>
   

   

    </sensor>

   


<keyframe>
     <key name="home" 
     qpos="0 0 0.244 1 0 0 0  
           -0.9 1.8 0 
           -0.9 1.8 0 
           -0.9 1.8 0 
           -0.9 1.8 0"
     ctrl=" -0.9 -0.9 -0.9 -0.9  
           1.8 1.8 1.8 1.8  
           0 0 0 0"/>

</keyframe>


</mujoco>
